{"name": "测试错误账号、正确密码情况下的登录", "status": "broken", "statusDetails": {"message": "AttributeError: 'list' object has no attribute 'items'", "trace": "cls = <class '_pytest.runner.CallInfo'>, func = <function call_and_report.<locals>.<lambda> at 0x0000024CFCF29580>\nwhen = 'setup', reraise = (<class '_pytest.outcomes.Exit'>, <class 'KeyboardInterrupt'>)\n\n    @classmethod\n    def from_call(\n        cls,\n        func: Callable[[], TResult],\n        when: Literal[\"collect\", \"setup\", \"call\", \"teardown\"],\n        reraise: type[BaseException] | tuple[type[BaseException], ...] | None = None,\n    ) -> CallInfo[TResult]:\n        \"\"\"Call func, wrapping the result in a CallInfo.\n    \n        :param func:\n            The function to call. Called without arguments.\n        :type func: Callable[[], _pytest.runner.TResult]\n        :param when:\n            The phase in which the function is called.\n        :param reraise:\n            Exception or exceptions that shall propagate if raised by the\n            function, instead of being wrapped in the CallInfo.\n        \"\"\"\n        excinfo = None\n        start = timing.time()\n        precise_start = timing.perf_counter()\n        try:\n>           result: TResult | None = func()\n\nD:\\Program Files (x86)\\python\\python311\\Lib\\site-packages\\_pytest\\runner.py:341: \n_ _ _ _ _ _ _ _ _ _ _ _ _ _ _ _ _ _ _ _ _ _ _ _ _ _ _ _ _ _ _ _ _ _ _ _ _ _ _ _ _ _ _ _ _ _ _ _ _ _ _ _ _ _ _ _ _ _ _ _\nD:\\Program Files (x86)\\python\\python311\\Lib\\site-packages\\_pytest\\runner.py:242: in <lambda>\n    lambda: runtest_hook(item=item, **kwds), when=when, reraise=reraise\nD:\\Program Files (x86)\\python\\python311\\Lib\\site-packages\\pluggy\\_hooks.py:513: in __call__\n    return self._hookexec(self.name, self._hookimpls.copy(), kwargs, firstresult)\nD:\\Program Files (x86)\\python\\python311\\Lib\\site-packages\\pluggy\\_manager.py:120: in _hookexec\n    return self._inner_hookexec(hook_name, methods, kwargs, firstresult)\nD:\\Program Files (x86)\\python\\python311\\Lib\\site-packages\\_pytest\\unraisableexception.py:90: in pytest_runtest_setup\n    yield from unraisable_exception_runtest_hook()\nD:\\Program Files (x86)\\python\\python311\\Lib\\site-packages\\_pytest\\unraisableexception.py:70: in unraisable_exception_runtest_hook\n    yield\nD:\\Program Files (x86)\\python\\python311\\Lib\\site-packages\\_pytest\\logging.py:842: in pytest_runtest_setup\n    yield from self._runtest_for(item, \"setup\")\nD:\\Program Files (x86)\\python\\python311\\Lib\\site-packages\\_pytest\\logging.py:831: in _runtest_for\n    yield\nD:\\Program Files (x86)\\python\\python311\\Lib\\site-packages\\_pytest\\capture.py:874: in pytest_runtest_setup\n    return (yield)\nD:\\Program Files (x86)\\python\\python311\\Lib\\site-packages\\_pytest\\threadexception.py:87: in pytest_runtest_setup\n    yield from thread_exception_runtest_hook()\nD:\\Program Files (x86)\\python\\python311\\Lib\\site-packages\\_pytest\\threadexception.py:68: in thread_exception_runtest_hook\n    yield\nD:\\Program Files (x86)\\python\\python311\\Lib\\site-packages\\_pytest\\runner.py:160: in pytest_runtest_setup\n    item.session._setupstate.setup(item)\n_ _ _ _ _ _ _ _ _ _ _ _ _ _ _ _ _ _ _ _ _ _ _ _ _ _ _ _ _ _ _ _ _ _ _ _ _ _ _ _ _ _ _ _ _ _ _ _ _ _ _ _ _ _ _ _ _ _ _ _\n\nself = <_pytest.runner.SetupState object at 0x0000024CFB954810>, item = <Function test_login_fail_case>\n\n    def setup(self, item: Item) -> None:\n        \"\"\"Setup objects along the collector chain to the item.\"\"\"\n        needed_collectors = item.listchain()\n    \n        # If a collector fails its setup, fail its entire subtree of items.\n        # The setup is not retried for each item - the same exception is used.\n>       for col, (finalizers, exc) in self.stack.items():\nE       AttributeError: 'list' object has no attribute 'items'\n\nD:\\Program Files (x86)\\python\\python311\\Lib\\site-packages\\_pytest\\runner.py:504: AttributeError"}, "description": "登录失败：测试错误账号、正确密码登录", "start": 1749457136651, "stop": 1749457136651, "uuid": "216d9405-2a04-42bb-af9c-bcbe28fdc9d2", "historyId": "fb5eb2d9aff400899ae5d6cfdecce615", "testCaseId": "fb5eb2d9aff400899ae5d6cfdecce615", "fullName": "test_dir.Login.test_002_loginfail.TestLoginFail#test_login_fail_case", "labels": [{"name": "feature", "value": "登录失败"}, {"name": "suite", "value": "登录"}, {"name": "parentSuite", "value": "test_dir.Login"}, {"name": "subSuite", "value": "TestLoginFail"}, {"name": "host", "value": "DESKTOP-9JRI8LF"}, {"name": "thread", "value": "19616-MainThread"}, {"name": "framework", "value": "pytest"}, {"name": "language", "value": "cpython3"}, {"name": "package", "value": "test_dir.Login.test_002_loginfail"}]}